2025-09-20 14:16:12,384 [ERROR] error_handler: ERROR_CONTEXT: {"timestamp": "2025-09-20T14:16:12.384141", "error_type": "ValueError", "error_message": "Test error", "severity": "error", "category": "system", "stack_trace": "Traceback (most recent call last):\n  File \"/home/zjp/Rn/claude-test-tsne/backend/src/middleware/graceful_degradation.py\", line 317, in process_with_degradation\n    yield context\n  File \"/home/zjp/Rn/claude-test-tsne/backend/tests/unit/middleware/test_graceful_degradation.py\", line 258, in test_process_with_degradation_error\n    raise ValueError(\"Test error\")\nValueError: Test error\n", "additional_info": {"context": {"operation": "test_operation", "degradation_level": "none", "available_features": ["real_time_updates", "advanced_visualization", "batch_processing", "export_high_quality", "data_cache", "performance_monitoring"], "duration_ms": 0.24247169494628906}}}
2025-09-20 14:16:12,386 [ERROR] error_handler: ERROR_CONTEXT: {"timestamp": "2025-09-20T14:16:12.385863", "error_type": "ValueError", "error_message": "Test error", "severity": "error", "category": "system", "stack_trace": "Traceback (most recent call last):\n  File \"/home/zjp/Rn/claude-test-tsne/backend/src/middleware/graceful_degradation.py\", line 317, in process_with_degradation\n    yield context\n  File \"/home/zjp/Rn/claude-test-tsne/backend/tests/unit/middleware/test_graceful_degradation.py\", line 271, in test_process_with_degradation_critical_error\n    raise ValueError(\"Test error\")\nValueError: Test error\n", "additional_info": {"context": {"operation": "test_operation", "degradation_level": "critical", "available_features": ["real_time_updates", "advanced_visualization", "batch_processing", "export_high_quality", "data_cache", "performance_monitoring"], "duration_ms": 0.1976490020751953}}}
2025-09-20 14:16:27,661 [ERROR] error_handler: ERROR_CONTEXT: {"timestamp": "2025-09-20T14:16:27.661097", "error_type": "ValueError", "error_message": "Invalid data format", "severity": "error", "category": "algorithm", "stack_trace": "NoneType: None\n", "additional_info": {"request_path": "/process", "method": "POST", "error_id": "e910def9-07a4-4128-a6b3-c3e07c1ca3ae"}}
2025-09-20 14:16:27,662 [ERROR] error_handler: ERROR_CONTEXT: {"timestamp": "2025-09-20T14:16:27.662579", "error_type": "KeyError", "error_message": "'missing_column'", "severity": "error", "category": "algorithm", "stack_trace": "NoneType: None\n", "additional_info": {"request_path": "/datasets", "method": "GET", "error_id": "962b3fa1-750d-4495-a423-5f554f5a28c0", "missing_key": "'missing_column'"}}
2025-09-20 14:16:27,664 [ERROR] error_handler: ERROR_CONTEXT: {"timestamp": "2025-09-20T14:16:27.664218", "error_type": "RuntimeError", "error_message": "Database connection failed", "severity": "critical", "category": "system", "stack_trace": "NoneType: None\n", "additional_info": {"request_path": "/api/data", "method": "GET", "error_id": "fe4f439f-0eb6-41dd-9aa1-ee6b90bec9dd", "exception_type": "RuntimeError"}}
2025-09-20 14:34:21,697 [ERROR] error_handler: ERROR_CONTEXT: {"timestamp": "2025-09-20T14:34:21.694940", "error_type": "HTTPException", "error_message": "500: 内部服务器错误", "severity": "critical", "category": "network", "stack_trace": "Traceback (most recent call last):\n  File \"/home/zjp/Rn/claude-test-tsne/backend/src/api/upload.py\", line 73, in upload_csv_file\n    raise HTTPException(\n    ...<2 lines>...\n    )\nfastapi.exceptions.HTTPException: 400: 文件名包含非法字符\n\nDuring handling of the above exception, another exception occurred:\n\nTraceback (most recent call last):\n  File \"/home/zjp/miniconda3/lib/python3.13/site-packages/starlette/_exception_handler.py\", line 42, in wrapped_app\n    await app(scope, receive, sender)\n  File \"/home/zjp/miniconda3/lib/python3.13/site-packages/starlette/routing.py\", line 75, in app\n    response = await f(request)\n               ^^^^^^^^^^^^^^^^\n  File \"/home/zjp/miniconda3/lib/python3.13/site-packages/fastapi/routing.py\", line 302, in app\n    raw_response = await run_endpoint_function(\n                   ^^^^^^^^^^^^^^^^^^^^^^^^^^^^\n    ...<3 lines>...\n    )\n    ^\n  File \"/home/zjp/miniconda3/lib/python3.13/site-packages/fastapi/routing.py\", line 213, in run_endpoint_function\n    return await dependant.call(**values)\n           ^^^^^^^^^^^^^^^^^^^^^^^^^^^^^^\n  File \"/home/zjp/Rn/claude-test-tsne/backend/src/api/upload.py\", line 103, in upload_csv_file\n    raise HTTPException(status_code=500, detail=\"内部服务器错误\")\nfastapi.exceptions.HTTPException: 500: 内部服务器错误\n", "additional_info": {"request_path": "/api/v1/upload/upload", "method": "POST", "error_id": "fde81b68-cefc-4264-99cd-41afad920eb1"}}
2025-09-20 14:34:33,893 [ERROR] error_handler: ERROR_CONTEXT: {"timestamp": "2025-09-20T14:34:33.892826", "error_type": "HTTPException", "error_message": "500: 内部服务器错误", "severity": "critical", "category": "network", "stack_trace": "Traceback (most recent call last):\n  File \"/home/zjp/Rn/claude-test-tsne/backend/src/api/upload.py\", line 73, in upload_csv_file\n    raise HTTPException(\n    ...<2 lines>...\n    )\nfastapi.exceptions.HTTPException: 400: 文件名包含非法字符\n\nDuring handling of the above exception, another exception occurred:\n\nTraceback (most recent call last):\n  File \"/home/zjp/miniconda3/lib/python3.13/site-packages/starlette/_exception_handler.py\", line 42, in wrapped_app\n    await app(scope, receive, sender)\n  File \"/home/zjp/miniconda3/lib/python3.13/site-packages/starlette/routing.py\", line 75, in app\n    response = await f(request)\n               ^^^^^^^^^^^^^^^^\n  File \"/home/zjp/miniconda3/lib/python3.13/site-packages/fastapi/routing.py\", line 302, in app\n    raw_response = await run_endpoint_function(\n                   ^^^^^^^^^^^^^^^^^^^^^^^^^^^^\n    ...<3 lines>...\n    )\n    ^\n  File \"/home/zjp/miniconda3/lib/python3.13/site-packages/fastapi/routing.py\", line 213, in run_endpoint_function\n    return await dependant.call(**values)\n           ^^^^^^^^^^^^^^^^^^^^^^^^^^^^^^\n  File \"/home/zjp/Rn/claude-test-tsne/backend/src/api/upload.py\", line 103, in upload_csv_file\n    raise HTTPException(status_code=500, detail=\"内部服务器错误\")\nfastapi.exceptions.HTTPException: 500: 内部服务器错误\n", "additional_info": {"request_path": "/api/v1/upload/upload", "method": "POST", "error_id": "2a43563d-619f-4e61-aa1d-462f8e7702eb"}}
2025-09-20 14:36:10,004 [ERROR] error_handler: ERROR_CONTEXT: {"timestamp": "2025-09-20T14:36:10.002535", "error_type": "HTTPException", "error_message": "500: 内部服务器错误", "severity": "critical", "category": "network", "stack_trace": "Traceback (most recent call last):\n  File \"/home/zjp/Rn/claude-test-tsne/backend/src/api/upload.py\", line 73, in upload_csv_file\n    raise HTTPException(\n    ...<2 lines>...\n    )\nfastapi.exceptions.HTTPException: 400: 文件名包含非法字符\n\nDuring handling of the above exception, another exception occurred:\n\nTraceback (most recent call last):\n  File \"/home/zjp/miniconda3/lib/python3.13/site-packages/starlette/_exception_handler.py\", line 42, in wrapped_app\n    await app(scope, receive, sender)\n  File \"/home/zjp/miniconda3/lib/python3.13/site-packages/starlette/routing.py\", line 75, in app\n    response = await f(request)\n               ^^^^^^^^^^^^^^^^\n  File \"/home/zjp/miniconda3/lib/python3.13/site-packages/fastapi/routing.py\", line 302, in app\n    raw_response = await run_endpoint_function(\n                   ^^^^^^^^^^^^^^^^^^^^^^^^^^^^\n    ...<3 lines>...\n    )\n    ^\n  File \"/home/zjp/miniconda3/lib/python3.13/site-packages/fastapi/routing.py\", line 213, in run_endpoint_function\n    return await dependant.call(**values)\n           ^^^^^^^^^^^^^^^^^^^^^^^^^^^^^^\n  File \"/home/zjp/Rn/claude-test-tsne/backend/src/api/upload.py\", line 103, in upload_csv_file\n    raise HTTPException(status_code=500, detail=\"内部服务器错误\")\nfastapi.exceptions.HTTPException: 500: 内部服务器错误\n", "additional_info": {"request_path": "/api/v1/upload/upload", "method": "POST", "error_id": "84e863fc-b98f-4666-bdf6-6428710bb586"}}
2025-09-20 14:38:06,697 [ERROR] error_handler: ERROR_CONTEXT: {"timestamp": "2025-09-20T14:38:06.695502", "error_type": "HTTPException", "error_message": "500: 内部服务器错误", "severity": "critical", "category": "network", "stack_trace": "Traceback (most recent call last):\n  File \"/home/zjp/Rn/claude-test-tsne/backend/src/services/upload_service.py\", line 91, in process_upload\n    dataset = await self._create_dataset(file, data, column_info, quality_score, encoding)\n              ^^^^^^^^^^^^^^^^^^^^^^^^^^^^^^^^^^^^^^^^^^^^^^^^^^^^^^^^^^^^^^^^^^^^^^^^^^^^\n  File \"/home/zjp/Rn/claude-test-tsne/backend/src/services/upload_service.py\", line 276, in _create_dataset\n    dataset = MOFDataset(\n        filename=file.filename or \"unknown.csv\",\n    ...<4 lines>...\n        data_quality_score=quality_score\n    )\n  File \"/home/zjp/miniconda3/lib/python3.13/site-packages/pydantic/main.py\", line 214, in __init__\n    validated_self = self.__pydantic_validator__.validate_python(data, self_instance=self)\npydantic_core._pydantic_core.ValidationError: 1 validation error for MOFDataset\nencoding\n  Value error, 不支持的编码格式: UTF-8-SIG [type=value_error, input_value='UTF-8-SIG', input_type=str]\n    For further information visit https://errors.pydantic.dev/2.10/v/value_error\n\nDuring handling of the above exception, another exception occurred:\n\nTraceback (most recent call last):\n  File \"/home/zjp/Rn/claude-test-tsne/backend/src/api/upload.py\", line 83, in upload_csv_file\n    dataset_info = await upload_service.process_upload(file)\n                   ^^^^^^^^^^^^^^^^^^^^^^^^^^^^^^^^^^^^^^^^^\n  File \"/home/zjp/Rn/claude-test-tsne/backend/src/services/upload_service.py\", line 107, in process_upload\n    raise HTTPException(status_code=400, detail=f\"文件处理失败: {str(e)}\")\nfastapi.exceptions.HTTPException: 400: 文件处理失败: 1 validation error for MOFDataset\nencoding\n  Value error, 不支持的编码格式: UTF-8-SIG [type=value_error, input_value='UTF-8-SIG', input_type=str]\n    For further information visit https://errors.pydantic.dev/2.10/v/value_error\n\nDuring handling of the above exception, another exception occurred:\n\nTraceback (most recent call last):\n  File \"/home/zjp/miniconda3/lib/python3.13/site-packages/starlette/_exception_handler.py\", line 42, in wrapped_app\n    await app(scope, receive, sender)\n  File \"/home/zjp/miniconda3/lib/python3.13/site-packages/starlette/routing.py\", line 75, in app\n    response = await f(request)\n               ^^^^^^^^^^^^^^^^\n  File \"/home/zjp/miniconda3/lib/python3.13/site-packages/fastapi/routing.py\", line 302, in app\n    raw_response = await run_endpoint_function(\n                   ^^^^^^^^^^^^^^^^^^^^^^^^^^^^\n    ...<3 lines>...\n    )\n    ^\n  File \"/home/zjp/miniconda3/lib/python3.13/site-packages/fastapi/routing.py\", line 213, in run_endpoint_function\n    return await dependant.call(**values)\n           ^^^^^^^^^^^^^^^^^^^^^^^^^^^^^^\n  File \"/home/zjp/Rn/claude-test-tsne/backend/src/api/upload.py\", line 104, in upload_csv_file\n    raise HTTPException(status_code=500, detail=\"内部服务器错误\")\nfastapi.exceptions.HTTPException: 500: 内部服务器错误\n", "additional_info": {"request_path": "/api/v1/upload/upload", "method": "POST", "error_id": "b1f9e95b-ceaa-4462-910b-f7a3cea48ad3"}}
2025-09-20 14:38:40,649 [ERROR] error_handler: ERROR_CONTEXT: {"timestamp": "2025-09-20T14:38:40.647771", "error_type": "HTTPException", "error_message": "500: 内部服务器错误", "severity": "critical", "category": "network", "stack_trace": "Traceback (most recent call last):\n  File \"/home/zjp/Rn/claude-test-tsne/backend/src/services/upload_service.py\", line 91, in process_upload\n    dataset = await self._create_dataset(file, data, column_info, quality_score, encoding)\n              ^^^^^^^^^^^^^^^^^^^^^^^^^^^^^^^^^^^^^^^^^^^^^^^^^^^^^^^^^^^^^^^^^^^^^^^^^^^^\n  File \"/home/zjp/Rn/claude-test-tsne/backend/src/services/upload_service.py\", line 276, in _create_dataset\n    dataset = MOFDataset(\n        filename=file.filename or \"unknown.csv\",\n    ...<4 lines>...\n        data_quality_score=quality_score\n    )\n  File \"/home/zjp/miniconda3/lib/python3.13/site-packages/pydantic/main.py\", line 214, in __init__\n    validated_self = self.__pydantic_validator__.validate_python(data, self_instance=self)\npydantic_core._pydantic_core.ValidationError: 1 validation error for MOFDataset\nencoding\n  Value error, 不支持的编码格式: UTF-8-SIG [type=value_error, input_value='UTF-8-SIG', input_type=str]\n    For further information visit https://errors.pydantic.dev/2.10/v/value_error\n\nDuring handling of the above exception, another exception occurred:\n\nTraceback (most recent call last):\n  File \"/home/zjp/Rn/claude-test-tsne/backend/src/api/upload.py\", line 83, in upload_csv_file\n    dataset_info = await upload_service.process_upload(file)\n                   ^^^^^^^^^^^^^^^^^^^^^^^^^^^^^^^^^^^^^^^^^\n  File \"/home/zjp/Rn/claude-test-tsne/backend/src/services/upload_service.py\", line 107, in process_upload\n    raise HTTPException(status_code=400, detail=f\"文件处理失败: {str(e)}\")\nfastapi.exceptions.HTTPException: 400: 文件处理失败: 1 validation error for MOFDataset\nencoding\n  Value error, 不支持的编码格式: UTF-8-SIG [type=value_error, input_value='UTF-8-SIG', input_type=str]\n    For further information visit https://errors.pydantic.dev/2.10/v/value_error\n\nDuring handling of the above exception, another exception occurred:\n\nTraceback (most recent call last):\n  File \"/home/zjp/miniconda3/lib/python3.13/site-packages/starlette/_exception_handler.py\", line 42, in wrapped_app\n    await app(scope, receive, sender)\n  File \"/home/zjp/miniconda3/lib/python3.13/site-packages/starlette/routing.py\", line 75, in app\n    response = await f(request)\n               ^^^^^^^^^^^^^^^^\n  File \"/home/zjp/miniconda3/lib/python3.13/site-packages/fastapi/routing.py\", line 302, in app\n    raw_response = await run_endpoint_function(\n                   ^^^^^^^^^^^^^^^^^^^^^^^^^^^^\n    ...<3 lines>...\n    )\n    ^\n  File \"/home/zjp/miniconda3/lib/python3.13/site-packages/fastapi/routing.py\", line 213, in run_endpoint_function\n    return await dependant.call(**values)\n           ^^^^^^^^^^^^^^^^^^^^^^^^^^^^^^\n  File \"/home/zjp/Rn/claude-test-tsne/backend/src/api/upload.py\", line 104, in upload_csv_file\n    raise HTTPException(status_code=500, detail=\"内部服务器错误\")\nfastapi.exceptions.HTTPException: 500: 内部服务器错误\n", "additional_info": {"request_path": "/api/v1/upload/upload", "method": "POST", "error_id": "60aca8aa-9d84-4d7f-be94-438f7456b10b"}}
2025-09-20 14:39:21,202 [ERROR] error_handler: ERROR_CONTEXT: {"timestamp": "2025-09-20T14:39:21.199979", "error_type": "HTTPException", "error_message": "500: 内部服务器错误", "severity": "critical", "category": "network", "stack_trace": "Traceback (most recent call last):\n  File \"/home/zjp/Rn/claude-test-tsne/backend/src/services/upload_service.py\", line 91, in process_upload\n    dataset = await self._create_dataset(file, data, column_info, quality_score, encoding)\n              ^^^^^^^^^^^^^^^^^^^^^^^^^^^^^^^^^^^^^^^^^^^^^^^^^^^^^^^^^^^^^^^^^^^^^^^^^^^^\n  File \"/home/zjp/Rn/claude-test-tsne/backend/src/services/upload_service.py\", line 276, in _create_dataset\n    dataset = MOFDataset(\n        filename=file.filename or \"unknown.csv\",\n    ...<4 lines>...\n        data_quality_score=quality_score\n    )\n  File \"/home/zjp/miniconda3/lib/python3.13/site-packages/pydantic/main.py\", line 214, in __init__\n    validated_self = self.__pydantic_validator__.validate_python(data, self_instance=self)\npydantic_core._pydantic_core.ValidationError: 1 validation error for MOFDataset\nencoding\n  Value error, 不支持的编码格式: UTF-8-SIG [type=value_error, input_value='UTF-8-SIG', input_type=str]\n    For further information visit https://errors.pydantic.dev/2.10/v/value_error\n\nDuring handling of the above exception, another exception occurred:\n\nTraceback (most recent call last):\n  File \"/home/zjp/Rn/claude-test-tsne/backend/src/api/upload.py\", line 83, in upload_csv_file\n    dataset_info = await upload_service.process_upload(file)\n                   ^^^^^^^^^^^^^^^^^^^^^^^^^^^^^^^^^^^^^^^^^\n  File \"/home/zjp/Rn/claude-test-tsne/backend/src/services/upload_service.py\", line 107, in process_upload\n    raise HTTPException(status_code=400, detail=f\"文件处理失败: {str(e)}\")\nfastapi.exceptions.HTTPException: 400: 文件处理失败: 1 validation error for MOFDataset\nencoding\n  Value error, 不支持的编码格式: UTF-8-SIG [type=value_error, input_value='UTF-8-SIG', input_type=str]\n    For further information visit https://errors.pydantic.dev/2.10/v/value_error\n\nDuring handling of the above exception, another exception occurred:\n\nTraceback (most recent call last):\n  File \"/home/zjp/miniconda3/lib/python3.13/site-packages/starlette/_exception_handler.py\", line 42, in wrapped_app\n    await app(scope, receive, sender)\n  File \"/home/zjp/miniconda3/lib/python3.13/site-packages/starlette/routing.py\", line 75, in app\n    response = await f(request)\n               ^^^^^^^^^^^^^^^^\n  File \"/home/zjp/miniconda3/lib/python3.13/site-packages/fastapi/routing.py\", line 302, in app\n    raw_response = await run_endpoint_function(\n                   ^^^^^^^^^^^^^^^^^^^^^^^^^^^^\n    ...<3 lines>...\n    )\n    ^\n  File \"/home/zjp/miniconda3/lib/python3.13/site-packages/fastapi/routing.py\", line 213, in run_endpoint_function\n    return await dependant.call(**values)\n           ^^^^^^^^^^^^^^^^^^^^^^^^^^^^^^\n  File \"/home/zjp/Rn/claude-test-tsne/backend/src/api/upload.py\", line 104, in upload_csv_file\n    raise HTTPException(status_code=500, detail=\"内部服务器错误\")\nfastapi.exceptions.HTTPException: 500: 内部服务器错误\n", "additional_info": {"request_path": "/api/v1/upload/upload", "method": "POST", "error_id": "f3aa9f06-c2fb-44b4-b3ae-d9010f07dfb1"}}
2025-09-20 18:51:19,641 [ERROR] error_handler: ERROR_CONTEXT: {"timestamp": "2025-09-20T18:51:19.638612", "error_type": "HTTPException", "error_message": "500: 内部服务器错误", "severity": "critical", "category": "network", "stack_trace": "Traceback (most recent call last):\n  File \"/home/zjp/Rn/claude-test-tsne/backend/src/services/upload_service.py\", line 129, in _save_temp_file\n    temp_file_path = self.temp_file_manager.create_temp_file(\n        prefix=\"upload_\",\n        suffix=\".csv\"\n    )\n  File \"/home/zjp/Rn/claude-test-tsne/backend/src/utils/temp_file_manager.py\", line 75, in create_temp_file\n    fd, temp_path = tempfile.mkstemp(\n                    ~~~~~~~~~~~~~~~~^\n        prefix=prefix,\n        ^^^^^^^^^^^^^^\n        suffix=suffix,\n        ^^^^^^^^^^^^^^\n        dir=str(self.temp_dir)\n        ^^^^^^^^^^^^^^^^^^^^^^\n    )\n    ^\n  File \"/home/zjp/miniconda3/lib/python3.13/tempfile.py\", line 357, in mkstemp\n    return _mkstemp_inner(dir, prefix, suffix, flags, output_type)\n  File \"/home/zjp/miniconda3/lib/python3.13/tempfile.py\", line 256, in _mkstemp_inner\n    fd = _os.open(file, flags, 0o600)\nFileNotFoundError: [Errno 2] No such file or directory: '/home/zjp/Rn/claude-test-tsne/backend/temp/upload_0ukzxnz7.csv'\n\nDuring handling of the above exception, another exception occurred:\n\nTraceback (most recent call last):\n  File \"/home/zjp/Rn/claude-test-tsne/backend/src/services/upload_service.py\", line 79, in process_upload\n    temp_file_path = await self._save_temp_file(file)\n                     ^^^^^^^^^^^^^^^^^^^^^^^^^^^^^^^^\n  File \"/home/zjp/Rn/claude-test-tsne/backend/src/services/upload_service.py\", line 151, in _save_temp_file\n    raise ValueError(f\"文件保存失败: {str(e)}\")\nValueError: 文件保存失败: [Errno 2] No such file or directory: '/home/zjp/Rn/claude-test-tsne/backend/temp/upload_0ukzxnz7.csv'\n\nDuring handling of the above exception, another exception occurred:\n\nTraceback (most recent call last):\n  File \"/home/zjp/Rn/claude-test-tsne/backend/src/api/upload.py\", line 83, in upload_csv_file\n    dataset_info = await upload_service.process_upload(file)\n                   ^^^^^^^^^^^^^^^^^^^^^^^^^^^^^^^^^^^^^^^^^\n  File \"/home/zjp/Rn/claude-test-tsne/backend/src/services/upload_service.py\", line 107, in process_upload\n    raise HTTPException(status_code=400, detail=f\"文件处理失败: {str(e)}\")\nfastapi.exceptions.HTTPException: 400: 文件处理失败: 文件保存失败: [Errno 2] No such file or directory: '/home/zjp/Rn/claude-test-tsne/backend/temp/upload_0ukzxnz7.csv'\n\nDuring handling of the above exception, another exception occurred:\n\nTraceback (most recent call last):\n  File \"/home/zjp/miniconda3/lib/python3.13/site-packages/starlette/_exception_handler.py\", line 42, in wrapped_app\n    await app(scope, receive, sender)\n  File \"/home/zjp/miniconda3/lib/python3.13/site-packages/starlette/routing.py\", line 75, in app\n    response = await f(request)\n               ^^^^^^^^^^^^^^^^\n  File \"/home/zjp/miniconda3/lib/python3.13/site-packages/fastapi/routing.py\", line 302, in app\n    raw_response = await run_endpoint_function(\n                   ^^^^^^^^^^^^^^^^^^^^^^^^^^^^\n    ...<3 lines>...\n    )\n    ^\n  File \"/home/zjp/miniconda3/lib/python3.13/site-packages/fastapi/routing.py\", line 213, in run_endpoint_function\n    return await dependant.call(**values)\n           ^^^^^^^^^^^^^^^^^^^^^^^^^^^^^^\n  File \"/home/zjp/Rn/claude-test-tsne/backend/src/api/upload.py\", line 104, in upload_csv_file\n    raise HTTPException(status_code=500, detail=\"内部服务器错误\")\nfastapi.exceptions.HTTPException: 500: 内部服务器错误\n", "additional_info": {"request_path": "/api/v1/upload/upload", "method": "POST", "error_id": "47e80242-74c3-4b12-8f56-9c2c3af987a9"}}
